Workbook

Sheet To do
H1: Lot 2, Trumbull - | K1: Questions | M1: Drawing
A2: Structural | B2: Rosenberg | C2: krystals@racivil.com | H2: 435-218-9510 | K2: Ceiling/Wall | M2: Manual J&D | O2: emailed
A3: Geo | B3: Gem | C3: brennan@gemenginc.com | K3: Niche | M3: Jones
A4: Permit | H4: Lot 3, Casey- 435-229-7948 | M4: Fitures
A5: Survey | M5: fans
A6: Sign | H6: Trumbell Bundy | K6: Wall Tile | M6: Switch legs
H7: 435 218 9510 | K7: Vanity mirror | M7: Panel Calcs
A8: Road Prep | B8: Dom Klesch | E8: 435-463-8210 | F8: Seth Newtson | K8: 120 Fixture problems | M8: Switching
A9: Well | B9: Dom Klesch | H9: Todd | K9: Wood floor Adu Closet | M9: Topo/Grading
A10: Power | B10: Dom Klesch | H10: 435 705 4264
A11: Gas | B11: Dom Klesch | K11: .
A12: Septic | B12: Dom Klesch
A13: Internet | B13: Dom Klesch
A15: Temp Facilities
A16: Excavation/Pad Prep/Backfill
A17: Concrete | B17: Randy Frie
A18: Foundatin Wall | B18: Randy Frie
A19: WaterProffing
A20: Termite
A22: Steel | B22: D Iron works
A23: Truss | B23: Sunpro | C23: smitcheel@sunpro.com
A24: Framing Material | B24: Sunroc | C24: smitcheel@sunpro.com
A25: Framing Labor | B25: Elwin | C25: gieframing502@gmail.com
A26: Stair
A28: EXT Doors | B28: Sunpro | C28: srmitchel@sunpro.com
A29: Windows | B29: STG | C29: nathan@lpbuildingsolutions.com
A30: Glass | B30: STG
A31: Roofing
A32: Roof Deck
A33: Roof Metal
A34: Stucco | B34: Simco
A35: Stone | B35: Simco
A36: Rammed Earth | B36: Clayworks | C36: ger@clay-works.com | E36: Allysa Oliver
A37: Rammed Earth Labor | B37: Woodland Stucco | C37: woodlandstuccoandpaint@gmail.com | F37: 30 int 40 Ex | H37: Labor only
A39: Mechanical | B39: Dash
A40: Plumbing | B40: Master | C40: office@masterplumbingsystems.com
A41: Gas | B41: Master | C41: office@masterplumbingsystems.com
A42: Plumbing Fixtures
A43: Electrical | B43: Dash
A44: Electrical Fixtures
...

Sheet Budget1
A1: Who is it Yes I meet that bunch of real cast like you know you got to watch you I this guy Got fucking indigestion from the sugar Yep Well yeah I feel like I know I've stabbed you you It's not too long that's just not fair to me Oh Whoops | B1: 646 W Liberty Lane | C1: =B4-C4 -> -7255.149 | D1: AKA 1025 S | E1: Kannerrville | F1: 84742
C2: 0.1
A3: Sq Ft | B3: =sum(L24:L28) -> 6993 | C3: Budget | D3: Budget | E3: CPF | F3: Duration | G3: Completion | I3: Pay Schedule | K3: Profit
A4: Build Gross | B4: =sum(B6:B92) -> 2846193.4 | C4: =sum(C7:C92) -> 2853448.5 | D4: =sum(D7:D92) -> 3088193.4 | E4: =sum(E20:E92) -> 363.66986 | F4: =sum(F5:F92) -> 383 | G4: =G92 -> 46127 | I4: =sum(I7:I95) -> 3089193.4 | K4: =C4-D4 -> -234744.85
A6: Deposit | B6: =sum(D7:D18) -> 545050 | L6: =I26 -> 603350 | M6: Cost to permit/deposit
A7: Plumbing Fixtures | B7: RAC | C7: 17000 | D7: =(C7*$C$2)+C7 -> 18700 | E7: =D7/$B$3 -> 2.6741027 | G7: 45689 | L7: =I32 -> 242000 | M7: 45991
A8: Electrical Fixtures | B8: RAC | C8: 18000 | D8: =(C8*$C$2)+C8 -> 19800 | E8: =D8/$B$3 -> 2.8314028 | G8: 45689 | L8: =I37 | M8: 46021
A9: Hidden Door | C9: 25000 | D9: =(C9*$C$2)+C9 -> 27500 | E9: =D9/$B$3 -> 3.9325039 | G9: 45689 | L9: =I39 -> 1000 | M9: 46052
A10: Vault Door | C10: 7500 | D10: =(C10*$C$2)+C10 -> 8250 | E10: =D10/$B$3 -> 1.1797512 | G10: 45689 | L10: =I41 | M10: 46081
A11: Cabinet | B11: Deez | C11: 26000 | D11: =(C11*$C$2)+C11 -> 28600 | E11: =D11/$B$3 -> 4.0898041 | G11: 45689 | L11: =I43 -> 187660 | M11: 46111
A12: Entry Stair | B12: TGC | C12: 17000 | D12: =(C12*$C$2)+C12 -> 18700 | E12: =D12/$B$3 -> 2.6741027 | G12: 45689 | L12: =I53 -> 262900 | M12: 46142
A13: Tile Material | B13: RAC | C13: 80000 | D13: =(C13*$C$2)+C13 -> 88000 | E13: =D13/$B$3 -> 12.584013 | G13: 45689 | L13: =I61 -> 415800 | M13: 46172
A14: Rammed Earth | B14: Alysa Oliver | C14: 50000 | D14: =(C14*$C$2)+C14 -> 55000 | E14: =D14/$B$3 -> 7.8650079 | G14: 45689 | L14: =I62 -> 78650 | M14: 46203
A15: Exterior Glass | B15: STG | C15: 115000 | D15: =(C15*$C$2)+C15 -> 126500 | E15: =D15/$B$3 -> 18.089518 | G15: 45689 | L15: =I73 -> 296450 | M15: 46233
A16: Rammed earth Material | B16: Clayworks | C16: 45000 | D16: =(C16*$C$2)+C16 -> 49500 | E16: =D16/$B$3 -> 7.0785071 | G16: 45689 | L16: =I81 -> 243100 | M16: 46264
A17: Railing | C17: 46000
A18: Range | B18: Action Target | C18: 95000 | D18: =(C18*$C$2)+C18 -> 104500 | E18: =D18/$B$3 -> 14.943515 | G18: 45689 | L18: =I87 -> 287650 | M18: 46295
A19: Permiting | B19: =sum(D20:D26) -> 58300 | L19: =I89 -> 27500 | M19: 46325
A20: Facilities | C20: 10000 | D20: =(C20*$C$2)+C20 -> 11000 | E20: =D20/$B$3 -> 1.5730016 | G20: 45689 | L20: =I91 -> 30800 | M20: 46356
A21: Permits | B21: Iron County | C21: 30000 | D21: =(C21*$C$2)+C21 -> 33000 | E21: =D21/$B$3 -> 4.7190047 | G21: 45690 | K21: Total | L21: =sum(L6:L20) -> 2676860
A22: Builders Risk | C22: 5000 | D22: =(C22*$C$2)+C22 -> 5500 | E22: =D22/$B$3 -> 0.78650079 | G22: 45691
A23: Manual J | C23: 1500 | D23: =(C23*$C$2)+C23 -> 1650 | E23: =D23/$B$3 -> 0.23595024 | G23: 45692
A24: Plans | B24: Steamroller | C24: 1000 | D24: =(C24*$C$2)+C24 -> 1100 | E24: =D24/$B$3 -> 0.15730016 | G24: 45693 | L24: 2181
A25: Soil | B25: Gem | C25: 3000 | D25: =(C25*$C$2)+C25 -> 3300 | E25: =D25/$B$3 -> 0.47190047 | G25: 45694 | L25: 409
A26: Inspections | C26: 2500 | D26: =(C26*$C$2)+C26 -> 2750 | E26: =D26/$B$3 -> 0.39325039 | G26: 45695 | I26: =B6+B19 -> 603350 | L26: 2206
A27: Site Utilities | B27: All right | L27: 919
A28: Site Utilities | C28: 122000 | D28: =(C28*$C$2)+C28 -> 134200 | E28: =D28/$B$3 -> 19.190619 | F28: 7 | G28: =WORKDAY(G26, F28) -> 45706 | L28: 1278
A29: Road | C29: 78000 | D29: =(C29*$C$2)+C29 -> 85800 | E29: =D29/$B$3 -> 12.269412 | F29: 14 | G29: =WORKDAY(G28, F29) -> 45726
A30: Gas | B30: RAC | C30: 10000 | D30: =(C30*$C$2)+C30 -> 11000 | E30: =D30/$B$3 -> 1.5730016 | F30: 2 | G30: =WORKDAY(G29, F30) -> 45728
A31: Power | C31: 5000 | D31: =(C31*$C$2)+C31 -> 5500 | E31: =D31/$B$3 -> 0.78650079 | F31: 5 | G31: =WORKDAY(G30, F31) -> 45735 | L31: 1979
A32: Water | C32: 5000 | D32: =(C32*$C$2)+C32 -> 5500 | E32: =D32/$B$3 -> 0.78650079 | F32: 4 | G32: =WORKDAY(G31, F32) -> 45741 | I32: =sum(D28:D32) -> 242000 | L32: 3229
A33: Structural | B33: =sum(D34:D43) -> 599993.36 | L33: =sum(L31:L32) -> 5208 | M33: =(D53+D85)/L33 -> 31.259601
A34: Ftgs | B34: Frie | C34: 35710.41 | D34: =(C34*$C$2)+C34 -> 39281.451 | E34: =D34/$B$3 -> 5.6172531 | F34: 7 | G34: =WORKDAY(G32, F34) -> 45750
A35: Wall | B35: Frie | C35: 63078 | D35: =(C35*$C$2)+C35 -> 69385.8 | E35: =D35/$B$3 -> 9.9221793 | F35: 7 | G35: =WORKDAY(G34, F35) -> 45761
A36: Slab | B36: Frie | C36: 49345.1 | D36: =(C36*$C$2)+C36 -> 54279.61 | E36: =D36/$B$3 -> 7.761992 | F36: 7 | G36: =WORKDAY(G35, F36) -> 45770
A37: Pan | B37: Frie | C37: 32075 | D37: =(C37*$C$2)+C37 -> 35282.5 | E37: =D37/$B$3 -> 5.0454025 | F37: 7 | G37: =WORKDAY(G36, F37) -> 45779
A38: Site | B38: Frie | C38: 9640 | D38: =(C38*$C$2)+C38 -> 10604 | E38: =D38/$B$3 -> 1.5163735 | F38: 7 | G38: =WORKDAY(G37, F38) -> 45790 | I38: =sum(D34:D38) -> 208833.36
A39: Pretreat | B39: RAC | C39: 1000 | D39: =(C39*$C$2)+C39 -> 1100 | E39: =D39/$B$3 -> 0.15730016 | F39: 7 | G39: =WORKDAY(G37, F39) -> 45790 | I39: =C39 -> 1000
A40: Steel | B40: D-Iron Works | C40: 184000 | D40: =(C40*$C$2)+C40 -> 202400 | E40: =D40/$B$3 -> 28.943229 | F40: 27 | G40: =WORKDAY(G39, F40) -> 45827 | I40: =C40 -> 184000
A41: Lumber | B41: Sunpro | C41: 50000 | D41: =(C41*$C$2)+C41 -> 55000 | E41: =D41/$B$3 -> 7.8650079 | G41: =WORKDAY(G40, F41) -> 45827
...

Sheet Sheet29
A2: ex | B2: Supply Prropne tank
B3: spec waterr collection tank
B4: include water pipe to collection
B5: spec waterr collection tank
B6: well tie in need add

Sheet Fixtures
A1: That's it | G1: Flooring | M1: Electircal Fixtures | P1: Flooring/Tile | S1: AV | V1: Solar
A2: Sinks | G2: Paver | H2: 2470 | I2: 11 | J2: =H2*I2 -> 27170
A3: Glacier Bay 33 | B3: 2 | C3: 300 | D3: Kitchen | G3: Pergo | H3: 1172 | I3: 3 | J3: =H3*I3 -> 3516
A4: Horrow Undermount | C4: 120 | D4: ADU | G4: Nashville | H4: 2636 | I4: 9 | J4: =H4*I4 -> 23724
A5: Horrow Undermount | C5: 120 | D5: Powder | G5: Carpet | H5: 950 | I5: 3 | J5: =H5*I5 -> 2850
A6: Horrow Undermount | C6: 120 | D6: Office | G6: Carra | H6: 783 | I6: 9 | J6: =H6*I6 -> 7047
A7: Horrow Undermount | C7: 120 | D7: ADU | G7: Wall Tile | H7: 755 | I7: 20 | J7: =H7*I7 -> 15100
A8: Horrow Undermount | C8: 240 | D8: Primary | G8: concrete Tile | H8: 600 | I8: 20 | J8: =H8*I8 -> 12000
A9: Mop Sink | C9: 319 | E9: Wand?
A10: Faucet | G10: Total | J10: =SUM(J2:J8) -> 91407
A11: Kohler Crue Touchless | B11: 2 | C11: 900 | D11: Kitchen
A12: Arc Waterfall | C12: 50 | D12: ADU | G12: Labor Floor | H12: =H3+H4+H6 -> 4591 | I12: 6 | J12: =H12*I12 -> 27546
A13: Arc Waterfall | C13: 50 | D13: Powder | G13: Labor Wall | H13: =H7+H8 -> 1355 | I13: 16 | J13: =H13*I13 -> 21680
A14: Arc Waterfall | C14: 50 | D14: Office | G14: Carpet | H14: =H5 -> 950 | I14: 3 | J14: =H14*I14 -> 2850
A15: Arc Waterfall | C15: 50 | D15: ADU
A16: Arc Waterfall | C16: 100 | D16: Primary | G16: total | J16: =sum(J12:J14) -> 52076
A17: Moen Wall Mount | C17: 140 | D17: Garage
A18: Toilet
A19: Horrow Unique | B19: 6 | C19: 6000
A20: Shower Valve
A21: Granjoy | B21: 3 | C21: 3000
A22: Tub | C22: 3500
A23: Tub Filler | C23: 1000
A24: Drains
A25: Oatey 24" Linear | B25: 3 | C25: 375
A26: Total | C26: =sum(C3:C25) -> 16554

Sheet Appliance
A2: Kitchen
A3: Appliance site | B3: http://www.thermador.com/
A4: 36" Refridge Column | B4: https://www.thermador.com/us/en/mkt-product/refrigeration/refrigerationrefrigerationcolumns/T36IR905SP
A5: 36" Freezer Column | B5: https://www.thermador.com/us/en/mkt-product/refrigeration/freezer-columns/T36IF905SP
A6: Double Oven | B6: https://www.thermador.com/us/en/mkt-product/ovens/double-ovens/MEDMC301WS
A7: Dishwasher | B7: https://www.thermador.com/us/en/mkt-product/dishwashers/custom-panel/DWHD640EPR
A8: Hood | B8: https://futurofuturo.com/54-skylight-ceiling-soffit-range-hood/?gad_source=1&gad_campaignid=22020168852&gbraid=0AAAAAD_hDAqqlhc5Adnrl7h_avAB-_94G&gclid=Cj0KCQjwxJvBBhDuARIsAGUgNfjVKi_F2Q8pLZHI8rJNJsrPAnkCamTcDZ1jcF-O4WFol61rn8Fug2caAnlzEALw_wcB
A9: Cooktop | B9: https://www.infinitysurfaces.it/invisible-induction-cooktop/
A10: Under Counter Fridge | B10: https://www.homedepot.com/p/TITTLA-24-in-Single-Zone-150-Can-Beverage-Refrigerator-in-Silver-with-2-Different-Door-Handles-Built-in-Beverage-Cooler-KMBR150/326580232
A11: Ice maker 400 | B11: https://www.homedepot.com/p/TITTLA-14-in-100-lbs-Full-Size-Ice-Cubes-per-day-Ice-Maker-with-Blue-LEDs-Interior-in-Silver-Stainless-Steel-HY45FT/326504176
A12: Ice maker 900 | B12: https://www.homedepot.com/p/COTLIN-15-in-22-lb-Built-In-Ice-Maker-in-Stainless-Steel-with-Reversible-Door-Crescent-Ice-IMC25BI/328501726
A14: ADU
A15: Package | B15: https://www.homedepot.com/p/sets/Frigidaire-25-6-cu-ft-Standard-Depth-Refrigerator-with-5-Burner-Freestanding-Electric-Range-and-Dishwasher/335525148
A16: Stack | B16: recomend
A19: Laundry | B19: recomend
A20: Washer | B20: recomend

Sheet Load
A1: What the fuck did I do with this shit man | B1: Calculated Load (A) | C1: Continuous Load x 125% | D1: Recommended Breaker | E1: Recommended Conductor (Cu) | F1: Recommended Conduit | K1: Amps
A2: Panel 1 | B2: 239 | C2: 298.8 | D2: 300 A | E2: 350 kcmil x 3 conductors + #2 AWG Ground | F2: 2.5" EMT (minimum)
A3: Panel 2 | B3: 250.5 | C3: 313.1 | D3: 300 A | E3: 350 kcmil x 3 conductors + #2 AWG Ground | F3: 2.5" EMT (minimum)
A4: Panel 3 | B4: 179.3 | C4: 224.1 | D4: 225 A | E4: 4/0 AWG x 3 conductors + #4 AWG Ground | F4: 2" EMT (minimum)
A5: Main Transformer | B5: 668.8 | C5: 836 | D5: 800 A Main | E5: Parallel 500 kcmil x 4 per phase + 1/0 Ground | F5: Dual 3" EMT runs (per phase)
A9: **TOTAL PANEL 1 LOAD**
A10: Lighting Loads | B10: Load | C10: Feet/Location | D10: Watts | E10: Load A | F10: Transformer | G10: Breaker | H10: NCL A
A11: Total | D11: =sum(D12:D53) -> 3228.9 | E11: =sum(E12:E32) -> 127.3375 | H11: =sum(H12:H32) -> 127.335
A12: Circuit 1 | B12: P1-EXT-1 | D12: 160.02 | E12: =D12/24 -> 6.6675 | F12: HDR-240-24 (10A) | G12: 7A | H12: 6.67 | I12: ShellY RGBWW Pro | J12: Dimmer
A13: Circuit 2 | B13: P1-EXT-2 | D13: 297.18 | E13: =D13/24 -> 12.3825 | F13: HDR-480-24 (20A) | G13: 15 A | H13: 12.38 | I13: ShellY RGBWW Pro | J13: Dimmer
A14: Circuit 3 | B14: P1-EXT-3 | D14: 228.6 | E14: =D14/24 -> 9.525 | F14: HDR-320-24 (13.3A) | G14: 10A | H14: 9.53 | I14: ShellY RGBWW Pro | J14: Dimmer
A15: Circuit 4 | B15: P1-EXT-4 | D15: 388.62 | E15: =D15/24 -> 16.1925 | F15: HDR-480-24 (20A) | G15: 20 A | H15: 16.19 | I15: ShellY RGBWW Pro | J15: Dimmer
A16: Circuit 5 | B16: P1-EXT-5 | D16: 274.32 | E16: =D16/24 -> 11.43 | F16: HDR-320-24 (13.3A) | G16: 15 A | H16: 11.43 | I16: ShellY RGBWW Pro | J16: Dimmer
A17: Circuit 6 | B17: P1-EXT-6 | D17: 320.04 | E17: =D17/24 -> 13.335 | F17: HDR-480-24 (20A) | G17: 15 A | H17: 13.33 | I17: ShellY RGBWW Pro | J17: Dimmer
A18: Circuit 7 | B18: P1-EXT-7 | D18: 274.32 | E18: =D18/24 -> 11.43 | F18: HDR-320-24 (13.3A) | G18: 15 A | H18: 11.43 | I18: ShellY RGBWW Pro | J18: Dimmer
A19: Circuit 8 | B19: P1-LVC-1 | C19: Kitchen Cooktop | D19: 168 | E19: =D19/24 -> 7 | F19: HDR-320-24 (13.3A) | G19: 15 A | H19: =D19/24 -> 7 | I19: ShellY RGBWW Pro | J19: Dimmer
A20: Circuit 1 | B20: P1-LVC-2 | C20: Kitchen dish Sink | D20: 72 | E20: =D20/24 -> 3 | F20: HDR-150-24 (5A) | G20: 7A | H20: =D20/24 -> 3 | I20: ShellY RGBWW Pro | J20: Dimmer
A21: Circuit 9 | B21: P1-LVC-3 | C21: Office | D21: 360 | E21: =D21/24 -> 15 | F21: HDR-480-24 (20A) | G21: 15 A | H21: =D21/24 -> 15 | I21: ShellY RGBWW Pro | J21: Dimmer
A22: Circuit 10 | B22: P1-LVM-1 | C22: Garge | D22: 36 | E22: =D22/24 -> 1.5 | F22: HDR-320-24 (20A) | G22: 15 A | H22: =sum(D22:D29)/24 -> 12 | I22: Shelly 1 PM
B23: P1-LVM-2 | C23: Systems Garage | D23: 18 | E23: =D23/24 -> 0.75 | F23: Combined 24V-10 | I23: Shelly 1 PM
B24: P1-LVM-3 | C24: Back Stair | D24: 36 | E24: =D24/24 -> 1.5 | F24: Combined 24V-10 | I24: tx | J24: Dimmer
B25: P1-LVM-4 | C25: Mechanical | D25: 18 | E25: =D25/24 -> 0.75 | F25: Combined 24V-10 | I25: Shelly 1 PM
B26: P1-LVM-5 | C26: Storage | D26: 18 | E26: =D26/24 -> 0.75 | F26: Combined 24V-10 | I26: Shelly 1 PM
B27: P1-LVM-6 | C27: Pantry | D27: 54 | E27: =D27/24 -> 2.25 | F27: Combined 24V-10 | I27: Shelly 1 PM
B28: P1-LVM-7 | C28: Office Closet | D28: 36 | E28: =D28/24 -> 1.5 | F28: Combined 24V-10 | I28: Shelly 1 PM
B29: P1-LB-8 | C29: Office Bath | D29: 72 | E29: =D29/24 -> 3 | F29: Combined 24V-10 | I29: Shelly 2 PM Pro-1.1 | J29: Dimmer
A30: Circuit 11 | B30: P1-L120-1 | C30: Powder | D30: 75 | E30: =D30/24 -> 3.125 | F30: HDR-480-24 (20A) | G30: 15 A | H30: =sum(D30:D32)/24 -> 9.375 | I30: Shelly 1 PM
B31: P1-L120-2 | C31: Island | D31: 75 | E31: =D31/24 -> 3.125 | F31: Combined 120V-11 | I31: Shelly 2 PM Pro-1.1 | J31: Dimmer
B32: P1-L120-3 | C32: Dining | D32: 75 | E32: =D32/24 -> 3.125 | F32: Combined 120V-11 | I32: Shelly 2 PM Pro-1.1 | J32: Dimmer
A33: Wall Loads
A34: Total | E34: =sum(E35:E53) -> 231.44 | H34: =sum(H35:H53) -> 294.44
A35: Circuit 12 | B35: P1-120-1 (120V) | E35: 16 | F35: 120V Circuit | G35: 40 A GFCI | H35: 16 | I35: Shelly PM-4-1.1
B36: P1-120-2 (120V) | E36: 16 | F36: 120V Circuit | H36: 16 | I36: Shelly PM-4-1.2
B37: P1-120-3 (120V) | E37: 16 | F37: 120V Circuit | H37: 16 | I37: Shelly PM-4-1.3
B38: P1-120-4 (120V) | E38: 16 | F38: 120V Circuit | H38: 16 | I38: Shelly PM-4-1.4
B39: P1-120-5 (120V) | E39: 16 | F39: 120V Circuit | G39: 40 A GFCI | H39: 16 | I39: Shelly PM-4-2.1
B40: P1-120-6 (120V) | H40: 16 | I40: Shelly PM-4-2.2
B41: P1-120-7 (120V) | H41: 16 | I41: Shelly PM-4-2.3
B42: P1-120-8 (120V) | H42: 16 | I42: Shelly PM-4-2.4
B43: P1-120-9 (120V) | G43: 15 | H43: 15 | I43: Shelly 1 PM
...

Sheet Schedule
A1: RAC Development | B1: Craig Engel RAC Inc. | C1: 724 S. 1220 W. Hurricane UT
A2: Tammy Engel | B2: racinc19@gmail.com | C2: Permit # PREP 23-440 | D2: Permit
A3: 1267 N 1390 W St. George UT | B3: 435-229-7360 | C3: Plans | D3: Plans
A4: racinc19billing@gmail.com | C4: Engineering | D4: Engineering
A5: 435-229-4759 | C5: Inspection | D5: Inspection Docs
C6: Selections | D6: Selections
A7: Trade | C7: Progress | E7: Start | F7: Days | G7: Finish | H7: Delay | I7: Notes
A8: -Duration | C8: =AVERAGE(C9:C135) -> 0.94104134 | D8: =IFERROR(__xludf.DUMMYFUNCTION("SPARKLINE(C8,{""charttype"",""bar"";""max"",1})"),"") | E8: =min(E9:E135) -> 45292 | F8: =G8-E8 -> 235 | G8: =MAX(G9:G135) -> 45527 | H8: =sum(H9:H138) -> 128
A9: Pre Construction | C9: =AVERAGE(C10:C16) -> 1 | D9: =IFERROR(__xludf.DUMMYFUNCTION("SPARKLINE(C9,{""charttype"",""bar"";""max"",1})"),"") | E9: =min(E10:E16) -> 45292 | F9: =G9-E9 -> 24 | G9: =MAX(G10:G16) -> 45316 | H9: =SUM(H10:H19) -> 0
A10: Construction Documents | C10: 1 | D10: =IFERROR(__xludf.DUMMYFUNCTION("SPARKLINE(C10,{""charttype"",""bar"";""max"",1})"),"") | E10: 45292 | F10: 1 | G10: =if(F10=0,G9, workday(E10,F10-1))+WORKDAY(H10,H9) -> 45292
A11: Manual J | C11: 1 | D11: =IFERROR(__xludf.DUMMYFUNCTION("SPARKLINE(C11,{""charttype"",""bar"";""max"",1})"),"") | E11: 45293 | F11: 0 | G11: =if(F11=0,G10, workday(E11,F11-1))+WORKDAY(H11,H10) -> 45292
A12: Selection File | C12: 1 | D12: =IFERROR(__xludf.DUMMYFUNCTION("SPARKLINE(C12,{""charttype"",""bar"";""max"",1})"),"") | E12: 45294 | F12: 0 | G12: =if(F12=0,G11, workday(E12,F12-1))+WORKDAY(H12,H11) -> 45292
A13: Schedule File | C13: 1 | D13: =IFERROR(__xludf.DUMMYFUNCTION("SPARKLINE(C13,{""charttype"",""bar"";""max"",1})"),"") | E13: 45295 | F13: 0 | G13: =if(F13=0,G12, workday(E13,F13-1))+WORKDAY(H13,H12) -> 45292
A14: Civial Engineering | C14: 1 | D14: =IFERROR(__xludf.DUMMYFUNCTION("SPARKLINE(C14,{""charttype"",""bar"";""max"",1})"),"") | E14: 45296 | F14: 1 | G14: =if(F14=0,G13, workday(E14,F14-1))+WORKDAY(H14,H13) -> 45296
A15: Structural Engineering | C15: 1 | D15: =IFERROR(__xludf.DUMMYFUNCTION("SPARKLINE(C15,{""charttype"",""bar"";""max"",1})"),"") | E15: 45297 | F15: 1 | G15: =if(F15=0,G14, workday(E15,F15-1))+WORKDAY(H15,H14) -> 45297
A16: Permit | C16: 1 | D16: =IFERROR(__xludf.DUMMYFUNCTION("SPARKLINE(C16,{""charttype"",""bar"";""max"",1})"),"") | E16: 45298 | F16: 15 | G16: =if(F16=0,G15, workday(E16,F16-1))+WORKDAY(H16,H15) -> 45316
A17: Material Deposits | C17: 1 | D17: =IFERROR(__xludf.DUMMYFUNCTION("SPARKLINE(C17,{""charttype"",""bar"";""max"",1})"),"") | E17: 45299 | F17: 15 | G17: =if(F17=0,G16, workday(E17,F17-1))+WORKDAY(H17,H16) -> 45317
A18: Temp Power | B18: I Tech Electric | C18: 1 | D18: =IFERROR(__xludf.DUMMYFUNCTION("SPARKLINE(C18,{""charttype"",""bar"";""max"",1})"),"") | E18: 45299 | F18: 1 | G18: =if(F18=0,G16, workday(E18,F18-1))+WORKDAY(H18,H16) -> 45299
A19: Job Sign | C19: 1 | D19: =IFERROR(__xludf.DUMMYFUNCTION("SPARKLINE(C19,{""charttype"",""bar"";""max"",1})"),"") | E19: 45355 | F19: 0 | G19: =if(F19=0,G18, workday(E19,F19-1))+WORKDAY(H19,H18) -> 45299
A20: Site Prep | C20: =average(C21:C26) -> 1 | D20: =IFERROR(__xludf.DUMMYFUNCTION("SPARKLINE(C20,{""charttype"",""bar"";""max"",1})"),"") | E20: =min(E21:E26) -> 45317 | F20: =G20-E20 -> 10 | G20: =MAX(G21:G26) -> 45327 | H20: =sum(H21:H26) -> 0
A21: Survey | C21: 1 | D21: =IFERROR(__xludf.DUMMYFUNCTION("SPARKLINE(C21,{""charttype"",""bar"";""max"",1})"),"") | E21: =workday(G16,1) -> 45317 | F21: 1 | G21: =if(F21=0,G20, workday(E21,F21-1))+WORKDAY(H21,H20) -> 45317
A22: Site Walls | C22: 1 | D22: =IFERROR(__xludf.DUMMYFUNCTION("SPARKLINE(C22,{""charttype"",""bar"";""max"",1})"),"") | E22: =workday(G21,1) -> 45320 | F22: 5 | G22: =if(F22=0,G21, workday(E22,F22-1))+WORKDAY(H22,H21) -> 45324
A23: Dumpster | C23: 1 | D23: =IFERROR(__xludf.DUMMYFUNCTION("SPARKLINE(C23,{""charttype"",""bar"";""max"",1})"),"") | E23: =workday(G22,1) -> 45327 | F23: 1 | G23: =if(F23=0,G22, workday(E23,F23-1))+WORKDAY(H23,H22) -> 45327
A24: Portable Toilet | C24: 1 | D24: =IFERROR(__xludf.DUMMYFUNCTION("SPARKLINE(C24,{""charttype"",""bar"";""max"",1})"),"") | E24: =workday(G23,1) -> 45328 | F24: 0 | G24: =if(F24=0,G23, workday(E24,F24-1))+WORKDAY(H24,H23) -> 45327
A25: Temp Water | C25: 1 | D25: =IFERROR(__xludf.DUMMYFUNCTION("SPARKLINE(C25,{""charttype"",""bar"";""max"",1})"),"") | E25: =workday(G24,1) -> 45328 | F25: 0 | G25: =if(F25=0,G24, workday(E25,F25-1))+WORKDAY(H25,H24) -> 45327
A26: Temp Electric Meter | C26: 1 | D26: =IFERROR(__xludf.DUMMYFUNCTION("SPARKLINE(C26,{""charttype"",""bar"";""max"",1})"),"") | E26: =workday(G25,1) -> 45328 | F26: 0 | G26: =if(F26=0,G25, workday(E26,F26-1))+WORKDAY(H26,H25) -> 45327
A27: Foundation | C27: =average(C28:C46) -> 1 | D27: =IFERROR(__xludf.DUMMYFUNCTION("SPARKLINE(C27,{""charttype"",""bar"";""max"",1})"),"") | E27: =min(E28:E46) -> 45292 | F27: =G27-E27 -> 78 | G27: =MAX(G28:G46) -> 45370 | H27: =sum(H28:H46) -> 42
A28: Strings | B28: RG QUALITY CONCRETE | C28: 1 | D28: =IFERROR(__xludf.DUMMYFUNCTION("SPARKLINE(C28,{""charttype"",""bar"";""max"",1})"),"") | E28: 45292 | F28: 1 | G28: =if(F28=0,E28, workday(E28,F28-1)) -> 45292
A29: Footing Dig | C29: 1 | D29: =IFERROR(__xludf.DUMMYFUNCTION("SPARKLINE(C29,{""charttype"",""bar"";""max"",1})"),"") | E29: =if(F29=0,E28,if(H28=0,workday(G28,1),workday(G28,H28))) -> 45293 | F29: 1 | G29: =if(F29=0,E29, workday(E29,F29-1)) -> 45293
A30: Place Pea Gravel | C30: 1 | D30: =IFERROR(__xludf.DUMMYFUNCTION("SPARKLINE(C30,{""charttype"",""bar"";""max"",1})"),"") | E30: =if(F30=0,E29,if(H29=0,workday(G29,1),workday(G29,H29))) -> 45294 | F30: 1 | G30: =if(F30=0,E30, workday(E30,F30-1)) -> 45294
A31: Footing Compaction Inspect | C31: 1 | D31: =IFERROR(__xludf.DUMMYFUNCTION("SPARKLINE(C31,{""charttype"",""bar"";""max"",1})"),"") | E31: =if(F31=0,E30,if(H30=0,workday(G30,1),workday(G30,H30))) -> 45295 | F31: 1 | G31: =if(F31=0,E31, workday(E31,F31-1)) -> 45295
A32: Setting Forms | C32: 1 | D32: =IFERROR(__xludf.DUMMYFUNCTION("SPARKLINE(C32,{""charttype"",""bar"";""max"",1})"),"") | E32: =if(F32=0,E31,if(H31=0,workday(G31,1),workday(G31,H31))) -> 45296 | F32: 1 | G32: =if(F32=0,E32, workday(E32,F32-1)) -> 45296
A33: Setting Rebar/Blockouts | C33: 1 | D33: =IFERROR(__xludf.DUMMYFUNCTION("SPARKLINE(C33,{""charttype"",""bar"";""max"",1})"),"") | E33: =if(F33=0,E32,if(H32=0,workday(G32,1),workday(G32,H32))) -> 45299 | F33: 1 | G33: =if(F33=0,E33, workday(E33,F33-1)) -> 45299 | H33: 40
A34: Underground Plumbing | B34: MASTER PLUMBING SYSTEMS | C34: 1 | D34: =IFERROR(__xludf.DUMMYFUNCTION("SPARKLINE(C34,{""charttype"",""bar"";""max"",1})"),"") | E34: =if(F34=0,E33,if(H33=0,workday(G33,1),workday(G33,H33))) -> 45355 | F34: 2 | G34: =if(F34=0,E34, workday(E34,F34-1)) -> 45356
A35: Plumbing Inspect | C35: 1 | D35: =IFERROR(__xludf.DUMMYFUNCTION("SPARKLINE(C35,{""charttype"",""bar"";""max"",1})"),"") | E35: =if(F35=0,E34,if(H34=0,workday(G34,1),workday(G34,H34))) -> 45357 | F35: 1 | G35: =if(F35=0,E35, workday(E35,F35-1)) -> 45357
A36: Pour Footings | C36: 1 | D36: =IFERROR(__xludf.DUMMYFUNCTION("SPARKLINE(C36,{""charttype"",""bar"";""max"",1})"),"") | E36: =if(F36=0,E35,if(H35=0,workday(G35,1),workday(G35,H35))) -> 45358 | F36: 1 | G36: =if(F36=0,E36, workday(E36,F36-1)) -> 45358
A37: Shade and fill | B37: RG QUALITY CONCRETE | C37: 1 | D37: =IFERROR(__xludf.DUMMYFUNCTION("SPARKLINE(C37,{""charttype"",""bar"";""max"",1})"),"") | E37: =if(F37=0,E36,if(H36=0,workday(G36,1),workday(G36,H36))) -> 45359 | F37: 1 | G37: =if(F37=0,E37, workday(E37,F37-1)) -> 45359
A38: Underground Electric | C38: 1 | D38: =IFERROR(__xludf.DUMMYFUNCTION("SPARKLINE(C38,{""charttype"",""bar"";""max"",1})"),"") | E38: =if(F38=0,E37,if(H37=0,workday(G37,1),workday(G37,H37))) -> 45362 | F38: 1 | G38: =if(F38=0,E38, workday(E38,F38-1)) -> 45362
A39: Termite | C39: 1 | D39: =IFERROR(__xludf.DUMMYFUNCTION("SPARKLINE(C39,{""charttype"",""bar"";""max"",1})"),"") | E39: =if(F39=0,E38,if(H38=0,workday(G38,1),workday(G38,H38))) -> 45362 | F39: 0 | G39: =if(F39=0,E39, workday(E39,F39-1)) -> 45362
A40: Slab inspection | C40: 1 | D40: =IFERROR(__xludf.DUMMYFUNCTION("SPARKLINE(C40,{""charttype"",""bar"";""max"",1})"),"") | E40: =if(F40=0,E39,if(H39=0,workday(G39,1),workday(G39,H39))) -> 45363 | F40: 1 | G40: =if(F40=0,E40, workday(E40,F40-1)) -> 45363
...

Sheet Tammy
A1: =Budget1!A1 -> Who is it Yes I meet that bunch of real cast like you know you got to watch you I this guy Got fucking indigestion from the sugar Yep Well yeah I feel like I know I've stabbed you you It's not too long that's just not fair to me Oh Whoops | B1: =Budget1!C3 -> Budget | C1: Date
A2: =Budget1!A2 | D2: Draw 1 | E2: Draw 2 | F2: Draw 3 | G2: Draw 4 | H2: Draw 5 | I2: Draw 6 | J2: Draw 7 | K2: Draw 8 | L2: Draw 9 | M2: Draw 10 | N2: Draw 11 | O2: Draw 12 | P2: Draw 13 | Q2: Draw 14 | R2: Draw 15 | S2: Draw 16 | T2: Draw 17
B3: Budget | C3: Outstanding
B4: =sum(B7:B95) -> 2775448.5 | C4: =sum(D4:T4)-B4 -> -2774723.5 | D4: =sum(D7:D95) -> 725 | E4: =sum(E7:E95) -> 0 | F4: =sum(F7:F95) -> 0 | G4: =sum(G7:G95) -> 0 | H4: =sum(H7:H95) -> 0 | I4: =sum(I7:I95) -> 0 | J4: =sum(J7:J95) -> 0 | K4: =sum(K7:K95) -> 0 | ... T4: =sum(T7:T95) -> 0
A5: =Budget1!A5 | B5: =Budget1!C5
A6: =Budget1!A6 -> Deposit | B6: =Budget1!C6
A7: =Budget1!A7 -> Plumbing Fixtures | B7: =Budget1!C7 -> 17000 | C7: =sum(D7:T7)-B7 -> -17000
A8: =Budget1!A8 -> Electrical Fixtures | B8: =Budget1!C8 -> 18000 | C8: =sum(D8:T8)-B8 -> -18000
A9: =Budget1!A9 -> Hidden Door | B9: =Budget1!C9 -> 25000 | C9: =sum(D9:T9)-B9 -> -25000
A10: =Budget1!A10 -> Vault Door | B10: =Budget1!C10 -> 7500 | C10: =sum(D10:T10)-B10 -> -7500
A11: =Budget1!A11 -> Cabinet | B11: =Budget1!C11 -> 26000 | C11: =sum(D11:T11)-B11 -> -26000
A12: =Budget1!A12 -> Entry Stair | B12: =Budget1!C12 -> 17000 | C12: =sum(D12:T12)-B12 -> -17000
A13: =Budget1!A13 -> Tile Material | B13: =Budget1!C13 -> 80000 | C13: =sum(D13:T13)-B13 -> -80000
A14: =Budget1!A14 -> Rammed Earth | B14: =Budget1!C14 -> 50000 | C14: =sum(D14:T14)-B14 -> -50000
A15: =Budget1!A15 -> Exterior Glass | B15: =Budget1!C15 -> 115000 | C15: =sum(D15:T15)-B15 -> -115000
A16: =Budget1!A16 -> Rammed earth Material | B16: =Budget1!C16 -> 45000 | C16: =sum(D16:T16)-B16 -> -45000
A17: =Budget1!A17 -> Railing | B17: =Budget1!C17 -> 46000 | C17: =sum(D17:T17)-B17 -> -46000
A18: =Budget1!A18 -> Range | B18: =Budget1!C18 -> 95000 | C18: =sum(D18:T18)-B18 -> -95000
A19: =Budget1!A19 -> Permiting | B19: =Budget1!C19
A20: =Budget1!A20 -> Facilities | B20: =Budget1!C20 -> 10000 | C20: =sum(D20:T20)-B20 -> -10000
A21: =Budget1!A21 -> Permits | B21: =Budget1!C21 -> 30000 | C21: =sum(D21:T21)-B21 -> -29275 | D21: =675+50 -> 725
A22: =Budget1!A22 -> Builders Risk | B22: =Budget1!C22 -> 5000 | C22: =sum(D22:T22)-B22 -> -5000
A23: =Budget1!A23 -> Manual J | B23: =Budget1!C23 -> 1500 | C23: =sum(D23:T23)-B23 -> -1500
A24: =Budget1!A24 -> Plans | B24: =Budget1!C24 -> 1000 | C24: =sum(D24:T24)-B24 -> -1000
A25: =Budget1!A25 -> Soil | B25: =Budget1!C25 -> 3000 | C25: =sum(D25:T25)-B25 -> -3000
A26: =Budget1!A26 -> Inspections | B26: =Budget1!C26 -> 2500 | C26: =sum(D26:T26)-B26 -> -2500
A27: =Budget1!A27 -> Site Utilities | B27: =Budget1!C27
A28: =Budget1!A28 -> Site Utilities | B28: =Budget1!C28 -> 122000 | C28: =sum(D28:T28)-B28 -> -122000
A29: =Budget1!A30 -> Gas | B29: =Budget1!C30 -> 10000 | C29: =sum(D29:T29)-B29 -> -10000
A30: =Budget1!A31 -> Power | B30: =Budget1!C31 -> 5000 | C30: =sum(D30:T30)-B30 -> -5000
A31: =Budget1!A32 -> Water | B31: =Budget1!C32 -> 5000 | C31: =sum(D31:T31)-B31 -> -5000
A32: =Budget1!A33 -> Structural | B32: =Budget1!C33
A33: =Budget1!A34 -> Ftgs | B33: =Budget1!C34 -> 35710.41 | C33: =sum(D33:T33)-B33 -> -35710.41
A34: =Budget1!A35 -> Wall | B34: =Budget1!C35 -> 63078 | C34: =sum(D34:T34)-B34 -> -63078
A35: =Budget1!A36 -> Slab | B35: =Budget1!C36 -> 49345.1 | C35: =sum(D35:T35)-B35 -> -49345.1
A36: =Budget1!A37 -> Pan | B36: =Budget1!C37 -> 32075 | C36: =sum(D36:T36)-B36 -> -32075
A37: =Budget1!A38 -> Site | B37: =Budget1!C38 -> 9640 | C37: =sum(D37:T37)-B37 -> -9640
A38: =Budget1!A39 -> Pretreat | B38: =Budget1!C39 -> 1000 | C38: =sum(D38:T38)-B38 -> -1000
A39: =Budget1!A40 -> Steel | B39: =Budget1!C40 -> 184000 | C39: =sum(D39:T39)-B39 -> -184000
A40: =Budget1!A41 -> Lumber | B40: =Budget1!C41 -> 50000 | C40: =sum(D40:T40)-B40 -> -50000
...

Sheet Budget
A1: Trade | B1: Sub | D1: Bid Amount | F1: Comment
A2: Total
A3: Lot 34
A4: Sq Ft | B4: 2345
A5: Cost per Ft. | B5: =D7/B4 -> 0
A6: LTV | B6: =G12/D8 -> 0
A8: Gross | B8: 0.15 | D8: =sum(D9:D14) -> 295216.99 | F8: =sum(F9:F14) -> 723091.55 | G8: 785000 | H8: 0.7
A9: Realtor | B9: 0.05 | D9: 40000 | F9: =G8*B9 -> 39250
A10: Profit | B10: 0.1 | D10: 80000
A12: Land | D12: 175000 | F12: =D12 -> 175000
A14: Build Cost | D14: =sum(D15:D83) -> 216.99 | F14: =sum(F15:F83) -> 508841.55 | G14: =G8*H8 -> 549500
A15: Interest | F15: =D15
A16: Origination | B16: 0.01 | F16: =D16
A18: Contingency
A19: Facilities | D19: 1.81 | F19: =$B$4*D19 -> 4244.45
A20: Engineering | D20: 1.27 | F20: =$B$4*D20 -> 2978.15
A21: Permits | B21: City of Hurricane | D21: 6.4 | F21: =$B$4*D21 -> 15008
A22: Builder Risk | D22: 1.81 | F22: =$B$4*D22 -> 4244.45
A23: Legal | D23: 1.81 | F23: =$B$4*D23 -> 4244.45
A24: WCD | D24: 4.27 | F24: =$B$4*D24 -> 10013.15
A25: Plans | B25: Steamroller | D25: 0.18 | F25: =$B$4*D25 -> 422.1
A26: Recorder | D26: 0.05 | F26: =$B$4*D26 -> 117.25
A27: Soil | B27: Landmark | D27: 0.54 | F27: =$B$4*D27 -> 1266.3
A28: Inspections | D28: 0.54 | F28: =$B$4*D28 -> 1266.3
A29: SWPPP | D29: 0.54 | F29: =$B$4*D29 -> 1266.3
A31: Pad Prep | D31: 2.72 | F31: =$B$4*D31 -> 6378.4
A32: Concrete | B32: Dixie, Ceasar, Sunset | D32: 12.69 | F32: =$B$4*D32 -> 29758.05
A33: Pretreat | B33: Morgan Pest Control | D33: 0.27 | F33: =$B$4*D33 -> 633.15
A34: Lumber | B34: Sunpro | D34: 7.25 | F34: =$B$4*D34 -> 17001.25
A35: Framing Labor | B35: BW, 5 DI, Bud | D35: 9.07 | F35: =$B$4*D35 -> 21269.15
A36: Truss | B36: SGT Truss | D36: 5.44 | F36: =$B$4*D36 -> 12756.8
F37: =$B$4*D37 -> 0
A38: Plumbing/Gas | B38: Bringhurst, Master | D38: 9.95 | F38: =$B$4*D38 -> 23332.75
A39: Plumbing Fixtures | B39: RAC | D39: 2.99 | F39: =$B$4*D39 -> 7011.55
A40: Water Heater | B40: RAC | F40: =$B$4*D40 -> 0
A41: Water Filtration | B41: Advanced | D41: 2.86 | F41: =$B$4*D41 -> 6706.7
A42: HVAC | B42: Kuhn's/Crofts | D42: 5.73 | F42: =$B$4*D42 -> 13436.85
A43: Fireplace | B43: Dixie | D43: 2.56 | F43: =$B$4*D43 -> 6003.2
A44: Electrical | B44: DHE.Copper.Breck | D44: 7.25 | F44: =$B$4*D44 -> 17001.25
A45: Electrical Fixtures | B45: RAC | D45: 3.63 | F45: =$B$4*D45 -> 8512.35
...
